Workbook

Sheet Inputs
A1: Kuzet AI — Cost Model Inputs
A2: Yellow = fill from Yandex meeting | Green = auto-calculated | Amber = unverified estimate
A4: 📐 Deployment Scale
A5: Total schools | B5: 1170 | C5: schools
A6: Cameras per school (avg) | B6: 27 | C6: cameras
A7: Total camera streams [= schools × cams] | B7: =Inputs!B5*Inputs!B6 | C7: streams
A8: Camera resolution | B8: 1080p
A9: Video codec | B9: H.265
A10: Bitrate per stream (Mbps) | B10: 1.5 | C10: Mbps
A12: ⏱ Operating Schedule
A13: School days per month | B13: 22 | C13: days
A14: Active hours per school day | B14: 12 | C14: hours
A15: Active hours / month [= days × hrs] | B15: =Inputs!B13*Inputs!B14 | C15: h/mo
A16: Concurrency factor (c) | B16: 0.55
A18: ☁️ Cloud GPU — Yandex T4i (VERIFIED: official KZT price-list, 2026-01-01)
A19: T4i GPU rate (₸/GPU·hour) | B19: 1191.0715 | C19: ₸/GPU·h
A20: T4i vCPU rate (₸/100%-vCPU·hour) | B20: 8.7 | C20: ₸/vCPU·h
A21: T4i RAM rate (₸/GB·hour) | B21: 2.3304 | C21: ₸/GB·h
A22: vCPUs per T4i VM | B22: 8 | C22: vCPU
A23: RAM per T4i VM (GB) | B23: 32 | C23: GB
A24: T4i box total rate (₸/h) [= GPU + vCPU×rate + RAM×rate] | B24: =Inputs!B18+Inputs!B19*Inputs!B20+Inputs!B21*Inputs!B22 | C24: ₸/h
A25: CVoS discount ⚠️ ESTIMATE — get from Yandex | B25: 0.2
A26: Streams per T4i GPU (S) ⚠️ UNBENCHMARKED — get from Yandex | B26: 40 | C26: streams/GPU
A28: ⚠️ T4i is the ONLY GPU Yandex offers in the Kazakhstan region today. A100/V100/H100 are Russia-region only (ru-central1). Confirm roadmap at meeting.
A30: ☁️ Cloud GPU — A100 80GB (⚠️ UNVERIFIED 3rd-party vendor)
A31: A100 rate (₸/hour) ⚠️ UNVERIFIED VENDOR | B31: 2500 | C31: ₸/h
A32: A100 monthly commit rate (₸/month) ⚠️ UNVERIFIED | B32: 890000 | C32: ₸/mo
A33: Streams per A100 GPU (S) ⚠️ UNBENCHMARKED | B33: 100 | C33: streams/GPU
A35: 🖥 Edge Hardware
A36: Edge box price (USD/unit) — Gaming PC RTX 4070 all-in | B36: 1450 | C36: USD
A37: USD → KZT exchange rate | B37: 490 | C37: ₸/$
A38: Boxes per school | B38: 1 | C38: boxes
A39: Hardware amortization years | B39: 5 | C39: years
A40: Spare/failure buffer | B40: 0.1
A41: Average power draw per box (W) | B41: 200 | C41: W
A42: Electricity rate (₸/kWh) | B42: 36.7 | C42: ₸/kWh
A43: School pays electricity? (1=yes, 0=no) | B43: 1
A45: ☁️ Cloud Non-GPU (Dashboard, DB, Storage, Alerts) ⚠️ ESTIMATE
A46: Cloud non-GPU monthly (₸/mo) ⚠️ ESTIMATE | B46: 500000 | C46: ₸/mo
A47: Event clip storage (GB/school/month) | B47: 10 | C47: GB/school/mo
...

Sheet Cloud Results
A1: Kuzet AI — Cloud Inference Cost (Scenario B)
A3: Parameter | B3: Yandex T4i | C3: A100 ⚠️ UNVERIF. | D3: Unit | E3: Notes
A4: Key Inputs (from Inputs sheet)
A5: Total streams | B5: =Inputs!B7
A6: Active hours/month | B6: =Inputs!B15
A7: Concurrency factor (c) | B7: =Inputs!B16
A8: S — streams/T4i (UNBENCHMARKED) | B8: =Inputs!B25 | C8: =Inputs!B29
A9: CVoS discount | B9: =Inputs!B24
A11: Cloud GPU Sizing
A12: Concurrent streams to serve [= total × c] | B12: =ROUND(Inputs!B7*Inputs!B16,0) | C12: =ROUND(Inputs!B7*Inputs!B16,0) | D12: streams
A13: GPUs required [= ceil(concurrent / S)] | B13: =CEILING(Inputs!B7*Inputs!B16/Inputs!B25,1) | C13: =CEILING(Inputs!B7*Inputs!B16/Inputs!B29,1) | D13: GPUs | E13: CEILING = always round up (safety-critical)
A14: GPU·hours per month [= GPUs × active_h] | B14: =CEILING(Inputs!B7*Inputs!B16/Inputs!B25,1)*Inputs!B15 | C14: =CEILING(Inputs!B7*Inputs!B16/Inputs!B29,1)*Inputs!B15 | D14: GPU·h/mo
A15: GPU·hours per year | B15: =CEILING(Inputs!B7*Inputs!B16/Inputs!B25,1)*Inputs!B15*12 | C15: =CEILING(Inputs!B7*Inputs!B16/Inputs!B29,1)*Inputs!B15*12 | D15: GPU·h/yr
A17: Cloud GPU Cost (₸)
A18: Monthly GPU cost [= GPUs × active_h × rate/h × (1−CVoS)] | B18: =CEILING(Inputs!B7*Inputs!B16/Inputs!B25,1)*Inputs!B15*Inputs!B23*(1-Inputs!B24) | C18: =CEILING(Inputs!B7*Inputs!B16/Inputs!B29,1)*Inputs!B15*Inputs!B27 | D18: ₸/mo | E18: A100: hourly × active_h (no CVoS applied — unverified vendor)
A19: Annual GPU cost | B19: =CEILING(Inputs!B7*Inputs!B16/Inputs!B25,1)*Inputs!B15*12*Inputs!B23*(1-Inputs!B24) | C19: =CEILING(Inputs!B7*Inputs!B16/Inputs!B29,1)*Inputs!B15*12*Inputs!B27 | D19: ₸/yr
A21: Cloud Non-GPU Cost (₸)
A22: Cloud non-GPU annual (dashboard/DB/storage/alerts) ⚠️ ESTIMATE | B22: =Inputs!B43*12 | C22: =Inputs!B43*12 | D22: ₸/yr | E22: ⚠️ ESTIMATE — get official rates from Yandex
A23: Event clip storage annual [= GB/school × schools × rate × 12] | B23: =Inputs!B44*Inputs!B5*Inputs!B45*12 | C23: =Inputs!B44*Inputs!B5*Inputs!B45*12 | D23: ₸/yr
A25: TOTAL Cloud Annual Cost (₸)
A26: TOTAL annual (fleet) | B26: =CEILING(Inputs!B7*Inputs!B16/Inputs!B25,1)*Inputs!B15*12*Inputs!B23*(1-Inputs!B24)+Inputs!B43*12+Inputs!B44*Inputs!B5*Inputs!B45*12 | C26: =CEILING(Inputs!B7*Inputs!B16/Inputs!B29,1)*Inputs!B15*12*Inputs!B27+Inputs!B43*12+Inputs!B44*Inputs!B5*Inputs!B45*12 | D26: ₸/yr
A27: Per school / year | B27: =(CEILING(Inputs!B7*Inputs!B16/Inputs!B25,1)*Inputs!B15*12*Inputs!B23*(1-Inputs!B24)+Inputs!B43*12+Inputs!B44*Inputs!B5*Inputs!B45*12)/Inputs!B5 | C27: =(CEILING(Inputs!B7*Inputs!B16/Inputs!B29,1)*Inputs!B15*12*Inputs!B27+Inputs!B43*12+Inputs!B44*Inputs!B5*Inputs!B45*12)/Inputs!B5 | D27: ₸/school/yr
A28: Per camera / month | B28: =(CEILING(Inputs!B7*Inputs!B16/Inputs!B25,1)*Inputs!B15*12*Inputs!B23*(1-Inputs!B24)+Inputs!B43*12+Inputs!B44*Inputs!B5*Inputs!B45*12)/Inputs!B7/12 | C28: =(CEILING(Inputs!B7*Inputs!B16/Inputs!B29,1)*Inputs!B15*12*Inputs!B27+Inputs!B43*12+Inputs!B44*Inputs!B5*Inputs!B45*12)/Inputs!B7/12 | D28: ₸/cam/mo
A31: ⚠️ All cloud figures assume S (streams/GPU) is the Inputs!B25/B29 value, which is UNBENCHMARKED. With the current Python/PyTorch code S≈1–5 (10–40× more GPUs, 10–40× more cost). These numbers only apply after a TensorRT/DeepStream rebuild.

Sheet Edge Results
A1: Kuzet AI — Edge-First Cost (Scenario A)
A3: Parameter | B3: Value | C3: Unit | D3: Notes
A4: Edge Hardware (one-time capex)
A5: Box price in KZT [= USD × FX] | B5: =Inputs!B33*Inputs!B34 | C5: ₸/box | D5: RTX 4070 gaming PC all-in ~$1,450 → ₸490 FX = ₸710,500
A6: Total boxes (1,170 schools × boxes/school) | B6: =Inputs!B5*Inputs!B35 | C6: boxes
A7: Total hardware capex [= boxes × price] | B7: =Inputs!B5*Inputs!B35*Inputs!B33*Inputs!B34 | C7: ₸ | D7: One-time purchase
A8: Capex with spares buffer [= capex × (1 + spare%)] | B8: =Inputs!B5*Inputs!B35*Inputs!B33*Inputs!B34*(1+Inputs!B37) | C8: ₸
A10: Annual Edge Hardware Cost (amortized)
A11: Annual hardware cost [= capex with spares ÷ amort years] | B11: =Inputs!B5*Inputs!B35*Inputs!B33*Inputs!B34*(1+Inputs!B37)/Inputs!B36 | C11: ₸/yr | D11: Straight-line, 5-yr
A13: Electricity (if Kuzet pays)
A14: Annual electricity [= boxes × W × 8760h × ₸/kWh ÷ 1000] (if Kuzet pays) | B14: =(1-Inputs!B39)*Inputs!B5*Inputs!B35*Inputs!B38*8760*Inputs!B40/1000 | C14: ₸/yr | D14: If school pays (Inputs!B39=1), this is ₸0. Electricity ₸36.7/kWh (GlobalPetrolPrices, Jun-2025).
A16: Cloud Retrain GPU (intermittent)
A17: Retrain GPU hours/year [= h/week × 52] | B17: =Inputs!B47*52 | C17: h/yr
A18: Retrain GPU cost/year [= hours × T4i rate/h × (1−CVoS)] | B18: =Inputs!B47*52*Inputs!B23*(1-Inputs!B24) | C18: ₸/yr | D18: One shared T4i VM, school-hours not relevant (batch, run anytime)
A20: Cloud Non-GPU (same as cloud scenario)
A21: Cloud non-GPU annual ⚠️ ESTIMATE | B21: =Inputs!B43*12 | C21: ₸/yr | D21: ⚠️ ESTIMATE — dashboard/DB/alerts/storage
A22: Event clip storage annual | B22: =Inputs!B44*Inputs!B5*Inputs!B45*12 | C22: ₸/yr | D22: Edge stores locally; cloud only for reviewed/flagged clips
A24: TOTAL Edge Annual Cost (₸)
A25: TOTAL annual (fleet) | B25: =Inputs!B5*Inputs!B35*Inputs!B33*Inputs!B34*(1+Inputs!B37)/Inputs!B36+(1-Inputs!B39)*Inputs!B5*Inputs!B35*Inputs!B38*8760*Inputs!B40/1000+Inputs!B47*52*Inputs!B23*(1-Inputs!B24)+Inputs!B43*12+Inputs!B44*Inputs!B5*Inputs!B45*12 | C25: ₸/yr
A26: Per school / year | B26: =(Inputs!B5*Inputs!B35*Inputs!B33*Inputs!B34*(1+Inputs!B37)/Inputs!B36+(1-Inputs!B39)*Inputs!B5*Inputs!B35*Inputs!B38*8760*Inputs!B40/1000+Inputs!B47*52*Inputs!B23*(1-Inputs!B24)+Inputs!B43*12+Inputs!B44*Inputs!B5*Inputs!B45*12)/Inputs!B5 | C26: ₸/school/yr
A27: Per camera / month | B27: =(Inputs!B5*Inputs!B35*Inputs!B33*Inputs!B34*(1+Inputs!B37)/Inputs!B36+(1-Inputs!B39)*Inputs!B5*Inputs!B35*Inputs!B38*8760*Inputs!B40/1000+Inputs!B47*52*Inputs!B23*(1-Inputs!B24)+Inputs!B43*12+Inputs!B44*Inputs!B5*Inputs!B45*12)/Inputs!B7/12 | C27: ₸/cam/mo
A28: One-time capex (hardware) | B28: =Inputs!B5*Inputs!B35*Inputs!B33*Inputs!B34*(1+Inputs!B37) | C28: ₸ | D28: Upfront hardware purchase

Sheet TCO Comparison
A1: Kuzet AI — 3-yr & 5-yr TCO + Break-Even
A3: Year | B3: Edge Cumulative ₸ | C3: Cloud T4i Cumulative ₸ | D3: Cloud A100 Cumulative ₸ | E3: Edge Annual ₸ | F3: Cloud T4i Annual ₸ | G3: Cloud A100 Annual ₸
A4: Year 1 | B4: =Inputs!B5*Inputs!B35*Inputs!B33*Inputs!B34*(1+Inputs!B37)+Inputs!B5*Inputs!B35*Inputs!B33*Inputs!B34*(1+Inputs!B37)/Inputs!B36+(1-Inputs!B39)*Inputs!B5*Inputs!B35*Inputs!B38*8760*Inputs!B40/1000+Inputs!B47*52*Inputs!B23*(1-Inputs!B24)+Inputs!B43*12+Inputs!B44*Inputs!B5*Inputs!B45*12 | C4: =CEILING(Inputs!B7*Inputs!B16/Inputs!B25,1)*Inputs!B15*12*Inputs!B23*(1-Inputs!B24)+Inputs!B43*12+Inputs!B44*Inputs!B5*Inputs!B45*12 | D4: =CEILING(Inputs!B7*Inputs!B16/Inputs!B29,1)*Inputs!B15*12*Inputs!B27+Inputs!B43*12+Inputs!B44*Inputs!B5*Inputs!B45*12 | E4: =Inputs!B5*Inputs!B35*Inputs!B33*Inputs!B34*(1+Inputs!B37)+Inputs!B5*Inputs!B35*Inputs!B33*Inputs!B34*(1+Inputs!B37)/Inputs!B36+(1-Inputs!B39)*Inputs!B5*Inputs!B35*Inputs!B38*8760*Inputs!B40/1000+Inputs!B47*52*Inputs!B23*(1-Inputs!B24)+Inputs!B43*12+Inputs!B44*Inputs!B5*Inputs!B45*12 | F4: =CEILING(Inputs!B7*Inputs!B16/Inputs!B25,1)*Inputs!B15*12*Inputs!B23*(1-Inputs!B24)+Inputs!B43*12+Inputs!B44*Inputs!B5*Inputs!B45*12 | G4: =CEILING(Inputs!B7*Inputs!B16/Inputs!B29,1)*Inputs!B15*12*Inputs!B27+Inputs!B43*12+Inputs!B44*Inputs!B5*Inputs!B45*12
A5: Year 2 | B5: =TCO!B4+Inputs!B5*Inputs!B35*Inputs!B33*Inputs!B34*(1+Inputs!B37)/Inputs!B36+(1-Inputs!B39)*Inputs!B5*Inputs!B35*Inputs!B38*8760*Inputs!B40/1000+Inputs!B47*52*Inputs!B23*(1-Inputs!B24)+Inputs!B43*12+Inputs!B44*Inputs!B5*Inputs!B45*12 | C5: =TCO!C4+CEILING(Inputs!B7*Inputs!B16/Inputs!B25,1)*Inputs!B15*12*Inputs!B23*(1-Inputs!B24)+Inputs!B43*12+Inputs!B44*Inputs!B5*Inputs!B45*12 | D5: =TCO!D4+CEILING(Inputs!B7*Inputs!B16/Inputs!B29,1)*Inputs!B15*12*Inputs!B27+Inputs!B43*12+Inputs!B44*Inputs!B5*Inputs!B45*12 | E5: =Inputs!B5*Inputs!B35*Inputs!B33*Inputs!B34*(1+Inputs!B37)/Inputs!B36+(1-Inputs!B39)*Inputs!B5*Inputs!B35*Inputs!B38*8760*Inputs!B40/1000+Inputs!B47*52*Inputs!B23*(1-Inputs!B24)+Inputs!B43*12+Inputs!B44*Inputs!B5*Inputs!B45*12 | F5: =CEILING(Inputs!B7*Inputs!B16/Inputs!B25,1)*Inputs!B15*12*Inputs!B23*(1-Inputs!B24)+Inputs!B43*12+Inputs!B44*Inputs!B5*Inputs!B45*12 | G5: =CEILING(Inputs!B7*Inputs!B16/Inputs!B29,1)*Inputs!B15*12*Inputs!B27+Inputs!B43*12+Inputs!B44*Inputs!B5*Inputs!B45*12
A6: Year 3 | B6: =TCO!B5+Inputs!B5*Inputs!B35*Inputs!B33*Inputs!B34*(1+Inputs!B37)/Inputs!B36+(1-Inputs!B39)*Inputs!B5*Inputs!B35*Inputs!B38*8760*Inputs!B40/1000+Inputs!B47*52*Inputs!B23*(1-Inputs!B24)+Inputs!B43*12+Inputs!B44*Inputs!B5*Inputs!B45*12 | C6: =TCO!C5+CEILING(Inputs!B7*Inputs!B16/Inputs!B25,1)*Inputs!B15*12*Inputs!B23*(1-Inputs!B24)+Inputs!B43*12+Inputs!B44*Inputs!B5*Inputs!B45*12 | D6: =TCO!D5+CEILING(Inputs!B7*Inputs!B16/Inputs!B29,1)*Inputs!B15*12*Inputs!B27+Inputs!B43*12+Inputs!B44*Inputs!B5*Inputs!B45*12 | E6: =Inputs!B5*Inputs!B35*Inputs!B33*Inputs!B34*(1+Inputs!B37)/Inputs!B36+(1-Inputs!B39)*Inputs!B5*Inputs!B35*Inputs!B38*8760*Inputs!B40/1000+Inputs!B47*52*Inputs!B23*(1-Inputs!B24)+Inputs!B43*12+Inputs!B44*Inputs!B5*Inputs!B45*12 | F6: =CEILING(Inputs!B7*Inputs!B16/Inputs!B25,1)*Inputs!B15*12*Inputs!B23*(1-Inputs!B24)+Inputs!B43*12+Inputs!B44*Inputs!B5*Inputs!B45*12 | G6: =CEILING(Inputs!B7*Inputs!B16/Inputs!B29,1)*Inputs!B15*12*Inputs!B27+Inputs!B43*12+Inputs!B44*Inputs!B5*Inputs!B45*12
A7: Year 4 | B7: =TCO!B6+Inputs!B5*Inputs!B35*Inputs!B33*Inputs!B34*(1+Inputs!B37)/Inputs!B36+(1-Inputs!B39)*Inputs!B5*Inputs!B35*Inputs!B38*8760*Inputs!B40/1000+Inputs!B47*52*Inputs!B23*(1-Inputs!B24)+Inputs!B43*12+Inputs!B44*Inputs!B5*Inputs!B45*12 | C7: =TCO!C6+CEILING(Inputs!B7*Inputs!B16/Inputs!B25,1)*Inputs!B15*12*Inputs!B23*(1-Inputs!B24)+Inputs!B43*12+Inputs!B44*Inputs!B5*Inputs!B45*12 | D7: =TCO!D6+CEILING(Inputs!B7*Inputs!B16/Inputs!B29,1)*Inputs!B15*12*Inputs!B27+Inputs!B43*12+Inputs!B44*Inputs!B5*Inputs!B45*12 | E7: =Inputs!B5*Inputs!B35*Inputs!B33*Inputs!B34*(1+Inputs!B37)/Inputs!B36+(1-Inputs!B39)*Inputs!B5*Inputs!B35*Inputs!B38*8760*Inputs!B40/1000+Inputs!B47*52*Inputs!B23*(1-Inputs!B24)+Inputs!B43*12+Inputs!B44*Inputs!B5*Inputs!B45*12 | F7: =CEILING(Inputs!B7*Inputs!B16/Inputs!B25,1)*Inputs!B15*12*Inputs!B23*(1-Inputs!B24)+Inputs!B43*12+Inputs!B44*Inputs!B5*Inputs!B45*12 | G7: =CEILING(Inputs!B7*Inputs!B16/Inputs!B29,1)*Inputs!B15*12*Inputs!B27+Inputs!B43*12+Inputs!B44*Inputs!B5*Inputs!B45*12
A8: Year 5 | B8: =TCO!B7+Inputs!B5*Inputs!B35*Inputs!B33*Inputs!B34*(1+Inputs!B37)/Inputs!B36+(1-Inputs!B39)*Inputs!B5*Inputs!B35*Inputs!B38*8760*Inputs!B40/1000+Inputs!B47*52*Inputs!B23*(1-Inputs!B24)+Inputs!B43*12+Inputs!B44*Inputs!B5*Inputs!B45*12 | C8: =TCO!C7+CEILING(Inputs!B7*Inputs!B16/Inputs!B25,1)*Inputs!B15*12*Inputs!B23*(1-Inputs!B24)+Inputs!B43*12+Inputs!B44*Inputs!B5*Inputs!B45*12 | D8: =TCO!D7+CEILING(Inputs!B7*Inputs!B16/Inputs!B29,1)*Inputs!B15*12*Inputs!B27+Inputs!B43*12+Inputs!B44*Inputs!B5*Inputs!B45*12 | E8: =Inputs!B5*Inputs!B35*Inputs!B33*Inputs!B34*(1+Inputs!B37)/Inputs!B36+(1-Inputs!B39)*Inputs!B5*Inputs!B35*Inputs!B38*8760*Inputs!B40/1000+Inputs!B47*52*Inputs!B23*(1-Inputs!B24)+Inputs!B43*12+Inputs!B44*Inputs!B5*Inputs!B45*12 | F8: =CEILING(Inputs!B7*Inputs!B16/Inputs!B25,1)*Inputs!B15*12*Inputs!B23*(1-Inputs!B24)+Inputs!B43*12+Inputs!B44*Inputs!B5*Inputs!B45*12 | G8: =CEILING(Inputs!B7*Inputs!B16/Inputs!B29,1)*Inputs!B15*12*Inputs!B27+Inputs!B43*12+Inputs!B44*Inputs!B5*Inputs!B45*12
A10: Summary
A11: 3-yr TCO Edge | B11: 3-yr TCO T4i | C11: 3-yr TCO A100 | D11: =TCO!D8
A12: 5-yr TCO Edge | B12: 5-yr TCO T4i | C12: 5-yr TCO A100 | D12: =TCO!D8
A14: ⚠️ Break-even depends on S (streams/GPU) and CVoS — both unverified. Cloud is opex-heavy (no upfront); edge is capex-heavy (large upfront + low opex). At default inputs, edge breaks even vs cloud T4i around Year 1–2.

Sheet Sensitivity
A1: Kuzet AI — Sensitivity: Cloud T4i Annual Cost vs S and Concurrency
A2: All figures in millions of ₸/year. Fixed inputs: school-hours 264h/mo, CVoS from Inputs!B24, non-GPU from Inputs!B43.
A4: S → / c ↓ | B4: S=5 | C4: S=10 | D4: S=20 | E4: S=40 | F4: S=60 | G4: S=80 | H4: S=100
A5: c=40% | B5: 8560.8 | C5: 4283.4 | D5: 2144.7 | E5: 1075.4 | F5: 720 | G5: 540.7 | H5: 435.8
A6: c=50% | B6: 10696.2 | C6: 5352.8 | D6: 2679.4 | E6: 1342.7 | F6: 899.4 | G6: 676 | H6: 540.7
A7: c=60% | B7: 12834.9 | C7: 6422.1 | D7: 3214.1 | E7: 1610 | F7: 1075.4 | G7: 808 | H7: 649
A8: c=70% | B8: 14973.6 | C8: 7491.5 | D8: 3748.7 | E8: 1877.4 | F8: 1254.7 | G8: 943.4 | H8: 757.3
A9: c=80% | B9: 17112.3 | C9: 8560.8 | D9: 4283.4 | E9: 2144.7 | F9: 1434.1 | G9: 1075.4 | H9: 862.2
A10: c=100% | B10: 21386.3 | C10: 10696.2 | D10: 5352.8 | E10: 2679.4 | F10: 1789.4 | G10: 1342.7 | H10: 1075.4
A12: Green < 500M ₸/yr | Yellow 500M–2B | Red > 2B. CVoS=20% and S values are ESTIMATES. Confirm both with Yandex expert.
